{
 "cells": [
  {
   "cell_type": "code",
   "execution_count": 1,
   "id": "af023b22",
   "metadata": {},
   "outputs": [],
   "source": [
    "import pandas as pd"
   ]
  },
  {
   "cell_type": "code",
   "execution_count": 2,
   "id": "85741262",
   "metadata": {},
   "outputs": [],
   "source": [
    "data = pd.read_excel('RISPOSTA_DOMANDA_30_Nov22_Apr23.xlsx')"
   ]
  },
  {
   "cell_type": "code",
   "execution_count": 4,
   "id": "6f24564c",
   "metadata": {},
   "outputs": [],
   "source": [
    "data.to_csv('output.csv')"
   ]
  },
  {
   "cell_type": "code",
   "execution_count": 6,
   "id": "7e4be26f",
   "metadata": {},
   "outputs": [
    {
     "name": "stderr",
     "output_type": "stream",
     "text": [
      "WARNING: Retrying (Retry(total=4, connect=None, read=None, redirect=None, status=None)) after connection broken by 'NewConnectionError('<pip._vendor.urllib3.connection.HTTPSConnection object at 0x0000017985599580>: Failed to establish a new connection: [Errno 11001] getaddrinfo failed')': /simple/langchain/\n",
      "WARNING: Retrying (Retry(total=3, connect=None, read=None, redirect=None, status=None)) after connection broken by 'NewConnectionError('<pip._vendor.urllib3.connection.HTTPSConnection object at 0x0000017985599460>: Failed to establish a new connection: [Errno 11001] getaddrinfo failed')': /simple/langchain/\n",
      "WARNING: Retrying (Retry(total=2, connect=None, read=None, redirect=None, status=None)) after connection broken by 'NewConnectionError('<pip._vendor.urllib3.connection.HTTPSConnection object at 0x0000017985599280>: Failed to establish a new connection: [Errno 11001] getaddrinfo failed')': /simple/langchain/\n",
      "WARNING: Retrying (Retry(total=1, connect=None, read=None, redirect=None, status=None)) after connection broken by 'NewConnectionError('<pip._vendor.urllib3.connection.HTTPSConnection object at 0x0000017985599F40>: Failed to establish a new connection: [Errno 11001] getaddrinfo failed')': /simple/langchain/\n",
      "WARNING: Retrying (Retry(total=0, connect=None, read=None, redirect=None, status=None)) after connection broken by 'NewConnectionError('<pip._vendor.urllib3.connection.HTTPSConnection object at 0x00000179855BE130>: Failed to establish a new connection: [Errno 11001] getaddrinfo failed')': /simple/langchain/\n",
      "ERROR: Could not find a version that satisfies the requirement langchain (from versions: none)\n",
      "ERROR: No matching distribution found for langchain\n"
     ]
    }
   ],
   "source": [
    "import sys\n",
    "!{sys.executable} -m pip install langchain"
   ]
  }
 ],
 "metadata": {
  "kernelspec": {
   "display_name": "Python 3 (ipykernel)",
   "language": "python",
   "name": "python3"
  },
  "language_info": {
   "codemirror_mode": {
    "name": "ipython",
    "version": 3
   },
   "file_extension": ".py",
   "mimetype": "text/x-python",
   "name": "python",
   "nbconvert_exporter": "python",
   "pygments_lexer": "ipython3",
   "version": "3.9.7"
  }
 },
 "nbformat": 4,
 "nbformat_minor": 5
}
